<?xml version="1.0"?>    
<robot xmlns:xacro="http://www.ros.org/wiki/xacro">    
    
  <xacro:macro name="custom_four_wheel_base" params="prefix">    

  <xacro:property
  name="meshes_file_direction"
  value="package://turtlebot3_manipulation_description/meshes/turtlebot3_waffle_pi"/>
        
    <!-- Base footprint -->    
    <link name="${prefix}base_footprint"/>    
        
    <!-- Base link -->    
    <joint name="${prefix}base_joint" type="fixed">    
      <parent link="${prefix}base_footprint"/>    
      <child link="${prefix}base_link"/>    
      <origin xyz="0.0 0.0 0.0675" rpy="0 0 0"/>    
    </joint>    
    
    <link name="${prefix}base_link">    
      <visual>    
        <origin xyz="0 0 0.05" rpy="0 0 0"/>    
        <geometry>    
          <box size="0.4 0.4 0.135"/>    
        </geometry>    
        <material name="grey">    
          <color rgba="0.5 0.5 0.5 1.0"/>    
        </material>    
      </visual>    
          
      <collision>    
        <origin xyz="0 0 0.05" rpy="0 0 0"/>    
        <geometry>    
          <box size="0.4 0.4 0.135"/>    
        </geometry>    
      </collision>    
          
      <inertial>    
        <origin xyz="-0.02 0 0.01" rpy="0 0 0"/>    
        <mass value="10.0"/>    
        <inertia ixx="0.2708" ixy="0.0" ixz="0.0"    
                 iyy="0.2708" iyz="0.0"    
                 izz="0.2667"/>    
      </inertial>    
    </link>    
    
    <!-- Left drive wheel -->    
    <joint name="${prefix}wheel_left_joint" type="continuous">    
      <parent link="${prefix}base_link"/>    
      <child link="${prefix}wheel_left_link"/>    
      <origin xyz="-0.14 0.185 0" rpy="-1.57 0 0"/>    
      <axis xyz="0 0 1"/>    
    </joint>    
    
    <link name="${prefix}wheel_left_link">    
      <visual>    
        <origin xyz="0 0 0" rpy="0 0 0"/>    
        <geometry>    
          <cylinder radius="0.0675" length="0.03"/>    
        </geometry>    
        <material name="black">    
          <color rgba="0.0 0.0 0.0 1.0"/>    
        </material>    
      </visual>    
          
      <collision>    
        <origin xyz="0 0 0" rpy="0 0 0"/>    
        <geometry>    
          <cylinder radius="0.0675" length="0.03"/>    
        </geometry>    
      </collision>    
          
      <inertial>    
        <origin xyz="0 0 0" rpy="0 0 0"/>    
        <mass value="0.5"/>    
        <inertia ixx="0.00114" ixy="0.0" ixz="0.0"    
                 iyy="0.00114" iyz="0.0"    
                 izz="0.00228"/>    
      </inertial>    
    </link>    
    
    <!-- Right drive wheel -->    
    <joint name="${prefix}wheel_right_joint" type="continuous">    
      <parent link="${prefix}base_link"/>    
      <child link="${prefix}wheel_right_link"/>    
      <origin xyz="-0.14 -0.185 0" rpy="-1.57 0 0"/>    
      <axis xyz="0 0 1"/>    
    </joint>    
    
    <link name="${prefix}wheel_right_link">    
      <visual>    
        <origin xyz="0 0 0" rpy="0 0 0"/>    
        <geometry>    
          <cylinder radius="0.0675" length="0.03"/>    
        </geometry>    
        <material name="black">    
          <color rgba="0.0 0.0 0.0 1.0"/>    
        </material>    
      </visual>    
          
      <collision>    
        <origin xyz="0 0 0" rpy="0 0 0"/>    
        <geometry>    
          <cylinder radius="0.0675" length="0.03"/>    
        </geometry>    
      </collision>    
          
      <inertial>    
        <origin xyz="0 0 0" rpy="0 0 0"/>    
        <mass value="0.5"/>    
        <inertia ixx="0.00114" ixy="0.0" ixz="0.0"    
                 iyy="0.00114" iyz="0.0"    
                 izz="0.00228"/>    
      </inertial>    
    </link>    
    
    <!-- Front left caster wheel -->    
    <joint name="${prefix}caster_front_left_joint" type="fixed">    
      <parent link="${prefix}base_link"/>    
      <child link="${prefix}caster_front_left_link"/>    
      <origin xyz="0.15 0.1 -0.0425" rpy="0 0 0"/>    
    </joint>    
    
    <link name="${prefix}caster_front_left_link">    
      <visual>    
        <origin xyz="0 0 0" rpy="0 0 0"/>    
        <geometry>    
          <sphere radius="0.025"/>    
        </geometry>    
        <material name="black">    
          <color rgba="0.0 0.0 0.0 1.0"/>    
        </material>    
      </visual>    
          
      <collision>    
        <origin xyz="0 0 0" rpy="0 0 0"/>    
        <geometry>    
          <sphere radius="0.025"/>    
        </geometry>    
      </collision>    
          
      <inertial>    
        <origin xyz="0 0 0" rpy="0 0 0"/>    
        <mass value="0.1"/>    
        <inertia ixx="0.00001" ixy="0.0" ixz="0.0"    
                 iyy="0.00001" iyz="0.0"    
                 izz="0.00001"/>    
      </inertial>    
    </link>    
    
    <!-- Front right caster wheel -->    
    <joint name="${prefix}caster_front_right_joint" type="fixed">    
      <parent link="${prefix}base_link"/>    
      <child link="${prefix}caster_front_right_link"/>    
      <origin xyz="0.15 -0.1 -0.0425" rpy="0 0 0"/>    
    </joint>    
    
    <link name="${prefix}caster_front_right_link">    
      <visual>    
        <origin xyz="0 0 0" rpy="0 0 0"/>    
        <geometry>    
          <sphere radius="0.025"/>    
        </geometry>    
        <material name="black">    
          <color rgba="0.0 0.0 0.0 1.0"/>    
        </material>    
      </visual>    
          
      <collision>    
        <origin xyz="0 0 0" rpy="0 0 0"/>    
        <geometry>    
          <sphere radius="0.025"/>    
        </geometry>    
      </collision>    
          
      <inertial>    
        <origin xyz="0 0 0" rpy="0 0 0"/>    
        <mass value="0.1"/>    
        <inertia ixx="0.00001" ixy="0.0" ixz="0.0"    
                 iyy="0.00001" iyz="0.0"    
                 izz="0.00001"/>    
      </inertial>    
    </link>    
  
    <joint name="${prefix}imu_joint" type="fixed">
      <parent link="${prefix}base_link"/>
      <child link="${prefix}imu_link"/>
      <origin xyz="0.0 0 0.068" rpy="0 0 0"/>
    </joint>

    <link name="${prefix}imu_link"/>

    <joint name="${prefix}scan_joint" type="fixed">
      <parent link="${prefix}base_link"/>
      <child link="${prefix}base_scan"/>
      <origin xyz="0.125 0 0.1375" rpy="0 0 0"/>
    </joint>

    <link name="${prefix}base_scan">
      <visual>
        <origin xyz="0 0 0.0" rpy="0 0 0"/>
        <geometry>
          <mesh filename="${meshes_file_direction}/ladar.stl" scale="0.001 0.001 0.001"/>
        </geometry>
        <material name="dark"/>
      </visual>

      <collision>
        <origin xyz="0.015 0 -0.0065" rpy="0 0 0"/>
        <geometry>
          <cylinder length="0.0315" radius="0.055"/>
        </geometry>
      </collision>

      <inertial>
        <mass value="0.114" />
        <origin xyz="0 0 0" />
        <inertia ixx="0.001" ixy="0.0" ixz="0.0"
                iyy="0.001" iyz="0.0"
                izz="0.001" />
      </inertial>
    </link>

    <joint name="${prefix}camera_joint" type="fixed">
      <parent link="${prefix}base_link"/>
      <child link="${prefix}camera_link"/>
      <origin xyz="0.201 0 0.1" rpy="0 0 0"/>
    </joint>

    <link name="${prefix}camera_link">
      <visual>
        <origin xyz="0.005 0.011 0.013" rpy="0 0 0"/>
        <geometry>
          <box size="0.015 0.030 0.02"/>
        </geometry>
      </visual>
      <collision>
        <origin xyz="0.005 0.011 0.013" rpy="0 0 0"/>
        <geometry>
          <box size="0.015 0.030 0.02"/>
        </geometry>
      </collision>
    </link>

    <joint name="${prefix}camera_rgb_joint" type="fixed">
      <parent link="${prefix}camera_link"/>
      <child link="${prefix}camera_rgb_frame"/>
      <origin xyz="0.003 0.011 0.009" rpy="0 0 0"/>
    </joint>

    <link name="${prefix}camera_rgb_frame"/>

    <joint name="${prefix}camera_rgb_optical_joint" type="fixed">
      <parent link="${prefix}camera_rgb_frame"/>
      <child link="${prefix}camera_rgb_optical_frame"/>
      <origin xyz="0 0 0" rpy="-1.57 0 -1.57"/>
    </joint>

    <link name="${prefix}camera_rgb_optical_frame"/>
    
  </xacro:macro>    
    
</robot>